{"step": "test_step", "status": "started", "timestamp": "2025-06-11T17:13:19.921557", "data": {}}
{"step": "test_step", "status": "completed", "timestamp": "2025-06-11T17:13:19.921716", "data": {}}
{"step": "test_step", "status": "failed", "timestamp": "2025-06-11T17:13:19.921787", "data": {"error": "Test error"}}
{"event": "file_upload", "filename": "test.wav", "size_mb": 1.5, "file_type": "audio/wav", "timestamp": "2025-06-11T17:13:19.921918"}
{"event": "error", "error_type": "ValueError", "error_message": "Test error", "context": "Test context", "traceback": "Traceback (most recent call last):\n  File \"/Users/kk/Code/whisperforge--prime/tests/test_basic_functionality.py\", line 32, in test_logging_functionality\n    raise ValueError(\"Test error\")\nValueError: Test error\n", "timestamp": "2025-06-11T17:13:19.922282"}
{"step": "test_step", "status": "started", "timestamp": "2025-06-11T17:20:35.628656", "data": {}}
{"step": "test_step", "status": "completed", "timestamp": "2025-06-11T17:20:35.628995", "data": {}}
{"step": "test_step", "status": "failed", "timestamp": "2025-06-11T17:20:35.629088", "data": {"error": "Test error"}}
{"event": "file_upload", "filename": "test.wav", "size_mb": 1.5, "file_type": "audio/wav", "timestamp": "2025-06-11T17:20:35.629298"}
{"event": "error", "error_type": "ValueError", "error_message": "Test error", "context": "Test context", "traceback": "Traceback (most recent call last):\n  File \"/Users/kk/Code/whisperforge--prime/tests/test_basic_functionality.py\", line 32, in test_logging_functionality\n    raise ValueError(\"Test error\")\nValueError: Test error\n", "timestamp": "2025-06-11T17:20:35.629942"}
{"event": "error", "error_type": "ValueError", "error_message": "Test error for logging", "context": "Test error context", "traceback": "Traceback (most recent call last):\n  File \"/Users/kk/Code/whisperforge--prime/tests/test_basic_functionality.py\", line 161, in test_logging_error_handling\n    raise ValueError(\"Test error for logging\")\nValueError: Test error for logging\n", "timestamp": "2025-06-11T17:20:35.847477"}
{"step": "test_step", "status": "started", "timestamp": "2025-06-11T17:21:14.934695", "data": {}}
{"step": "test_step", "status": "completed", "timestamp": "2025-06-11T17:21:14.934969", "data": {}}
{"step": "test_step", "status": "failed", "timestamp": "2025-06-11T17:21:14.935054", "data": {"error": "Test error"}}
{"event": "file_upload", "filename": "test.wav", "size_mb": 1.5, "file_type": "audio/wav", "timestamp": "2025-06-11T17:21:14.935283"}
{"event": "error", "error_type": "ValueError", "error_message": "Test error", "context": "Test context", "traceback": "Traceback (most recent call last):\n  File \"/Users/kk/Code/whisperforge--prime/tests/test_basic_functionality.py\", line 32, in test_logging_functionality\n    raise ValueError(\"Test error\")\nValueError: Test error\n", "timestamp": "2025-06-11T17:21:14.935714"}
{"event": "error", "error_type": "ValueError", "error_message": "Test error for logging", "context": "Test error context", "traceback": "Traceback (most recent call last):\n  File \"/Users/kk/Code/whisperforge--prime/tests/test_basic_functionality.py\", line 165, in test_logging_error_handling\n    raise ValueError(\"Test error for logging\")\nValueError: Test error for logging\n", "timestamp": "2025-06-11T17:21:15.117631"}
{"step": "test_step", "status": "started", "timestamp": "2025-06-11T17:21:33.922723", "data": {}}
{"step": "test_step", "status": "completed", "timestamp": "2025-06-11T17:21:33.922949", "data": {}}
{"step": "test_step", "status": "failed", "timestamp": "2025-06-11T17:21:33.923035", "data": {"error": "Test error"}}
{"event": "file_upload", "filename": "test.wav", "size_mb": 1.5, "file_type": "audio/wav", "timestamp": "2025-06-11T17:21:33.923279"}
{"event": "error", "error_type": "ValueError", "error_message": "Test error", "context": "Test context", "traceback": "Traceback (most recent call last):\n  File \"/Users/kk/Code/whisperforge--prime/tests/test_basic_functionality.py\", line 32, in test_logging_functionality\n    raise ValueError(\"Test error\")\nValueError: Test error\n", "timestamp": "2025-06-11T17:21:33.923731"}
{"event": "error", "error_type": "ValueError", "error_message": "Test error for logging", "context": "Test error context", "traceback": "Traceback (most recent call last):\n  File \"/Users/kk/Code/whisperforge--prime/tests/test_basic_functionality.py\", line 167, in test_logging_error_handling\n    raise ValueError(\"Test error for logging\")\nValueError: Test error for logging\n", "timestamp": "2025-06-11T17:21:34.104706"}
{"step": "test_step", "status": "started", "timestamp": "2025-06-11T17:25:36.774685", "data": {}}
{"step": "test_step", "status": "completed", "timestamp": "2025-06-11T17:25:36.774991", "data": {}}
{"step": "test_step", "status": "failed", "timestamp": "2025-06-11T17:25:36.775077", "data": {"error": "Test error"}}
{"event": "file_upload", "filename": "test.wav", "size_mb": 1.5, "file_type": "audio/wav", "timestamp": "2025-06-11T17:25:36.775306"}
{"event": "error", "error_type": "ValueError", "error_message": "Test error", "context": "Test context", "traceback": "Traceback (most recent call last):\n  File \"/Users/kk/Code/whisperforge--prime/tests/test_basic_functionality.py\", line 32, in test_logging_functionality\n    raise ValueError(\"Test error\")\nValueError: Test error\n", "timestamp": "2025-06-11T17:25:36.775969"}
{"event": "error", "error_type": "ValueError", "error_message": "Test error for logging", "context": "Test error context", "traceback": "Traceback (most recent call last):\n  File \"/Users/kk/Code/whisperforge--prime/tests/test_basic_functionality.py\", line 167, in test_logging_error_handling\n    raise ValueError(\"Test error for logging\")\nValueError: Test error for logging\n", "timestamp": "2025-06-11T17:25:36.945974"}
{"step": "test_step", "status": "started", "timestamp": "2025-06-11T17:25:37.508561", "data": {}}
{"step": "test_step", "status": "completed", "timestamp": "2025-06-11T17:25:37.508707", "data": {}}
{"step": "test_step", "status": "failed", "timestamp": "2025-06-11T17:25:37.508973", "data": {"error": "Test error"}}
{"event": "file_upload", "filename": "test.wav", "size_mb": 1.5, "file_type": "audio/wav", "timestamp": "2025-06-11T17:25:37.509102"}
{"event": "ai_request", "provider": "openai", "model": "whisper-1", "prompt_type": "transcription", "tokens": null, "timestamp": "2025-06-11T17:25:37.509162"}
{"event": "user_action", "action": "upload_file", "user_id": "test-user", "details": {}, "timestamp": "2025-06-11T17:25:37.509216"}
{"event": "error", "error_type": "ValueError", "error_message": "Test error", "context": "Test context", "traceback": "Traceback (most recent call last):\n  File \"/Users/kk/Code/whisperforge--prime/tests/test_core_functionality.py\", line 294, in test_logging_functionality\n    raise ValueError(\"Test error\")\nValueError: Test error\n", "timestamp": "2025-06-11T17:25:37.509450"}
{"step": "test_step", "status": "started", "timestamp": "2025-06-11T17:27:03.812926", "data": {}}
{"step": "test_step", "status": "completed", "timestamp": "2025-06-11T17:27:03.813243", "data": {}}
{"step": "test_step", "status": "failed", "timestamp": "2025-06-11T17:27:03.813340", "data": {"error": "Test error"}}
{"event": "file_upload", "filename": "test.wav", "size_mb": 1.5, "file_type": "audio/wav", "timestamp": "2025-06-11T17:27:03.813476"}
{"event": "error", "error_type": "ValueError", "error_message": "Test error", "context": "Test context", "traceback": "Traceback (most recent call last):\n  File \"/Users/kk/Code/whisperforge--prime/tests/test_basic_functionality.py\", line 32, in test_logging_functionality\n    raise ValueError(\"Test error\")\nValueError: Test error\n", "timestamp": "2025-06-11T17:27:03.813949"}
{"event": "error", "error_type": "ValueError", "error_message": "Test error for logging", "context": "Test error context", "traceback": "Traceback (most recent call last):\n  File \"/Users/kk/Code/whisperforge--prime/tests/test_basic_functionality.py\", line 167, in test_logging_error_handling\n    raise ValueError(\"Test error for logging\")\nValueError: Test error for logging\n", "timestamp": "2025-06-11T17:27:03.970897"}
{"step": "test_step", "status": "started", "timestamp": "2025-06-11T19:07:43.278697", "data": {}}
{"step": "test_step", "status": "completed", "timestamp": "2025-06-11T19:07:43.279010", "data": {}}
{"step": "test_step", "status": "failed", "timestamp": "2025-06-11T19:07:43.279105", "data": {"error": "Test error"}}
{"event": "file_upload", "filename": "test.wav", "size_mb": 1.5, "file_type": "audio/wav", "timestamp": "2025-06-11T19:07:43.279248"}
{"event": "error", "error_type": "ValueError", "error_message": "Test error", "context": "Test context", "traceback": "Traceback (most recent call last):\n  File \"/Users/kk/Code/whisperforge--prime/tests/test_basic_functionality.py\", line 32, in test_logging_functionality\n    raise ValueError(\"Test error\")\nValueError: Test error\n", "timestamp": "2025-06-11T19:07:43.279828"}
{"event": "error", "error_type": "ValueError", "error_message": "Test error for logging", "context": "Test error context", "traceback": "Traceback (most recent call last):\n  File \"/Users/kk/Code/whisperforge--prime/tests/test_basic_functionality.py\", line 167, in test_logging_error_handling\n    raise ValueError(\"Test error for logging\")\nValueError: Test error for logging\n", "timestamp": "2025-06-11T19:07:43.416148"}
{"event": "error", "error_type": "ValueError", "error_message": "SUPABASE_URL and SUPABASE_ANON_KEY must be set in environment variables", "context": "Failed to initialize Supabase", "traceback": "Traceback (most recent call last):\n  File \"/Users/kk/Code/whisperforge--prime/core/auth_wrapper.py\", line 30, in _init_supabase\n    self.supabase_client = get_supabase_client()\n                           ~~~~~~~~~~~~~~~~~~~^^\n  File \"/Users/kk/Code/whisperforge--prime/core/supabase_integration.py\", line 397, in get_supabase_client\n    _supabase_client = SupabaseClient()\n  File \"/Users/kk/Code/whisperforge--prime/core/supabase_integration.py\", line 36, in __init__\n    raise ValueError(\"SUPABASE_URL and SUPABASE_ANON_KEY must be set in environment variables\")\nValueError: SUPABASE_URL and SUPABASE_ANON_KEY must be set in environment variables\n", "timestamp": "2025-06-11T19:07:43.480280"}
{"event": "error", "error_type": "ValueError", "error_message": "SUPABASE_URL and SUPABASE_ANON_KEY must be set in environment variables", "context": "Failed to initialize Supabase", "traceback": "Traceback (most recent call last):\n  File \"/Users/kk/Code/whisperforge--prime/core/auth_wrapper.py\", line 30, in _init_supabase\n    self.supabase_client = get_supabase_client()\n                           ~~~~~~~~~~~~~~~~~~~^^\n  File \"/Users/kk/Code/whisperforge--prime/core/supabase_integration.py\", line 397, in get_supabase_client\n    _supabase_client = SupabaseClient()\n  File \"/Users/kk/Code/whisperforge--prime/core/supabase_integration.py\", line 36, in __init__\n    raise ValueError(\"SUPABASE_URL and SUPABASE_ANON_KEY must be set in environment variables\")\nValueError: SUPABASE_URL and SUPABASE_ANON_KEY must be set in environment variables\n", "timestamp": "2025-06-11T19:07:43.481300"}
{"event": "error", "error_type": "AttributeError", "error_message": "'WhisperForgeLogger' object has no attribute 'info'", "context": "Authentication error for test@example.com", "traceback": "Traceback (most recent call last):\n  File \"/Users/kk/Code/whisperforge--prime/core/auth_wrapper.py\", line 53, in authenticate_user\n    logger.info(f\"Authentication attempt for: {email}\")\n    ^^^^^^^^^^^\nAttributeError: 'WhisperForgeLogger' object has no attribute 'info'\n", "timestamp": "2025-06-11T19:07:43.481518"}
{"event": "error", "error_type": "ValueError", "error_message": "SUPABASE_URL and SUPABASE_ANON_KEY must be set in environment variables", "context": "Failed to initialize Supabase", "traceback": "Traceback (most recent call last):\n  File \"/Users/kk/Code/whisperforge--prime/core/auth_wrapper.py\", line 30, in _init_supabase\n    self.supabase_client = get_supabase_client()\n                           ~~~~~~~~~~~~~~~~~~~^^\n  File \"/Users/kk/Code/whisperforge--prime/core/supabase_integration.py\", line 397, in get_supabase_client\n    _supabase_client = SupabaseClient()\n  File \"/Users/kk/Code/whisperforge--prime/core/supabase_integration.py\", line 36, in __init__\n    raise ValueError(\"SUPABASE_URL and SUPABASE_ANON_KEY must be set in environment variables\")\nValueError: SUPABASE_URL and SUPABASE_ANON_KEY must be set in environment variables\n", "timestamp": "2025-06-11T19:07:43.484519"}
{"event": "error", "error_type": "AttributeError", "error_message": "'WhisperForgeLogger' object has no attribute 'info'", "context": "Authentication error for nonexistent@example.com", "traceback": "Traceback (most recent call last):\n  File \"/Users/kk/Code/whisperforge--prime/core/auth_wrapper.py\", line 53, in authenticate_user\n    logger.info(f\"Authentication attempt for: {email}\")\n    ^^^^^^^^^^^\nAttributeError: 'WhisperForgeLogger' object has no attribute 'info'\n", "timestamp": "2025-06-11T19:07:43.484767"}
{"event": "error", "error_type": "ValueError", "error_message": "SUPABASE_URL and SUPABASE_ANON_KEY must be set in environment variables", "context": "Failed to initialize Supabase", "traceback": "Traceback (most recent call last):\n  File \"/Users/kk/Code/whisperforge--prime/core/auth_wrapper.py\", line 30, in _init_supabase\n    self.supabase_client = get_supabase_client()\n                           ~~~~~~~~~~~~~~~~~~~^^\n  File \"/Users/kk/Code/whisperforge--prime/core/supabase_integration.py\", line 397, in get_supabase_client\n    _supabase_client = SupabaseClient()\n  File \"/Users/kk/Code/whisperforge--prime/core/supabase_integration.py\", line 36, in __init__\n    raise ValueError(\"SUPABASE_URL and SUPABASE_ANON_KEY must be set in environment variables\")\nValueError: SUPABASE_URL and SUPABASE_ANON_KEY must be set in environment variables\n", "timestamp": "2025-06-11T19:07:43.485705"}
{"event": "error", "error_type": "AttributeError", "error_message": "'WhisperForgeLogger' object has no attribute 'info'", "context": "Authentication error for test@example.com", "traceback": "Traceback (most recent call last):\n  File \"/Users/kk/Code/whisperforge--prime/core/auth_wrapper.py\", line 53, in authenticate_user\n    logger.info(f\"Authentication attempt for: {email}\")\n    ^^^^^^^^^^^\nAttributeError: 'WhisperForgeLogger' object has no attribute 'info'\n", "timestamp": "2025-06-11T19:07:43.485914"}
{"event": "error", "error_type": "ValueError", "error_message": "SUPABASE_URL and SUPABASE_ANON_KEY must be set in environment variables", "context": "Failed to initialize Supabase", "traceback": "Traceback (most recent call last):\n  File \"/Users/kk/Code/whisperforge--prime/core/auth_wrapper.py\", line 30, in _init_supabase\n    self.supabase_client = get_supabase_client()\n                           ~~~~~~~~~~~~~~~~~~~^^\n  File \"/Users/kk/Code/whisperforge--prime/core/supabase_integration.py\", line 397, in get_supabase_client\n    _supabase_client = SupabaseClient()\n  File \"/Users/kk/Code/whisperforge--prime/core/supabase_integration.py\", line 36, in __init__\n    raise ValueError(\"SUPABASE_URL and SUPABASE_ANON_KEY must be set in environment variables\")\nValueError: SUPABASE_URL and SUPABASE_ANON_KEY must be set in environment variables\n", "timestamp": "2025-06-11T19:07:43.486878"}
{"event": "error", "error_type": "AttributeError", "error_message": "'WhisperForgeLogger' object has no attribute 'info'", "context": "Authentication error for test@example.com", "traceback": "Traceback (most recent call last):\n  File \"/Users/kk/Code/whisperforge--prime/core/auth_wrapper.py\", line 53, in authenticate_user\n    logger.info(f\"Authentication attempt for: {email}\")\n    ^^^^^^^^^^^\nAttributeError: 'WhisperForgeLogger' object has no attribute 'info'\n", "timestamp": "2025-06-11T19:07:43.487091"}
{"event": "error", "error_type": "ValueError", "error_message": "SUPABASE_URL and SUPABASE_ANON_KEY must be set in environment variables", "context": "Failed to initialize Supabase", "traceback": "Traceback (most recent call last):\n  File \"/Users/kk/Code/whisperforge--prime/core/auth_wrapper.py\", line 30, in _init_supabase\n    self.supabase_client = get_supabase_client()\n                           ~~~~~~~~~~~~~~~~~~~^^\n  File \"/Users/kk/Code/whisperforge--prime/core/supabase_integration.py\", line 397, in get_supabase_client\n    _supabase_client = SupabaseClient()\n  File \"/Users/kk/Code/whisperforge--prime/core/supabase_integration.py\", line 36, in __init__\n    raise ValueError(\"SUPABASE_URL and SUPABASE_ANON_KEY must be set in environment variables\")\nValueError: SUPABASE_URL and SUPABASE_ANON_KEY must be set in environment variables\n", "timestamp": "2025-06-11T19:07:43.490242"}
{"event": "error", "error_type": "AttributeError", "error_message": "'WhisperForgeLogger' object has no attribute 'info'", "context": "Registration error for new@example.com", "traceback": "Traceback (most recent call last):\n  File \"/Users/kk/Code/whisperforge--prime/core/auth_wrapper.py\", line 139, in register_user\n    logger.info(f\"User registered successfully: {email}\")\n    ^^^^^^^^^^^\nAttributeError: 'WhisperForgeLogger' object has no attribute 'info'\n", "timestamp": "2025-06-11T19:07:43.490577"}
{"event": "error", "error_type": "ValueError", "error_message": "SUPABASE_URL and SUPABASE_ANON_KEY must be set in environment variables", "context": "Failed to initialize Supabase", "traceback": "Traceback (most recent call last):\n  File \"/Users/kk/Code/whisperforge--prime/core/auth_wrapper.py\", line 30, in _init_supabase\n    self.supabase_client = get_supabase_client()\n                           ~~~~~~~~~~~~~~~~~~~^^\n  File \"/Users/kk/Code/whisperforge--prime/core/supabase_integration.py\", line 397, in get_supabase_client\n    _supabase_client = SupabaseClient()\n  File \"/Users/kk/Code/whisperforge--prime/core/supabase_integration.py\", line 36, in __init__\n    raise ValueError(\"SUPABASE_URL and SUPABASE_ANON_KEY must be set in environment variables\")\nValueError: SUPABASE_URL and SUPABASE_ANON_KEY must be set in environment variables\n", "timestamp": "2025-06-11T19:07:43.493544"}
{"event": "error", "error_type": "AttributeError", "error_message": "'WhisperForgeLogger' object has no attribute 'info'", "context": "Error updating API key openai_api_key", "traceback": "Traceback (most recent call last):\n  File \"/Users/kk/Code/whisperforge--prime/core/auth_wrapper.py\", line 229, in update_api_key\n    logger.info(f\"API key updated: {key_name}\")\n    ^^^^^^^^^^^\nAttributeError: 'WhisperForgeLogger' object has no attribute 'info'\n", "timestamp": "2025-06-11T19:07:43.493873"}
{"event": "error", "error_type": "SupabaseException", "error_message": "Invalid API key", "context": "Failed to initialize Supabase", "traceback": "Traceback (most recent call last):\n  File \"/Users/kk/Code/whisperforge--prime/core/auth_wrapper.py\", line 30, in _init_supabase\n    self.supabase_client = get_supabase_client()\n                           ~~~~~~~~~~~~~~~~~~~^^\n  File \"/Users/kk/Code/whisperforge--prime/core/supabase_integration.py\", line 397, in get_supabase_client\n    _supabase_client = SupabaseClient()\n  File \"/Users/kk/Code/whisperforge--prime/core/supabase_integration.py\", line 38, in __init__\n    self.client: Client = create_client(self.url, self.key)\n                          ~~~~~~~~~~~~~^^^^^^^^^^^^^^^^^^^^\n  File \"/Users/kk/Code/whisperforge--prime/venv/lib/python3.13/site-packages/supabase/_sync/client.py\", line 341, in create_client\n    return SyncClient.create(\n           ~~~~~~~~~~~~~~~~~^\n        supabase_url=supabase_url, supabase_key=supabase_key, options=options\n        ^^^^^^^^^^^^^^^^^^^^^^^^^^^^^^^^^^^^^^^^^^^^^^^^^^^^^^^^^^^^^^^^^^^^^\n    )\n    ^\n  File \"/Users/kk/Code/whisperforge--prime/venv/lib/python3.13/site-packages/supabase/_sync/client.py\", line 103, in create\n    client = cls(supabase_url, supabase_key, options)\n  File \"/Users/kk/Code/whisperforge--prime/venv/lib/python3.13/site-packages/supabase/_sync/client.py\", line 64, in __init__\n    raise SupabaseException(\"Invalid API key\")\nsupabase._sync.client.SupabaseException: Invalid API key\n", "timestamp": "2025-06-11T19:13:27.099230"}
{"event": "error", "error_type": "SupabaseException", "error_message": "Invalid API key", "context": "Failed to initialize Supabase", "traceback": "Traceback (most recent call last):\n  File \"/Users/kk/Code/whisperforge--prime/core/auth_wrapper.py\", line 30, in _init_supabase\n    self.supabase_client = get_supabase_client()\n                           ~~~~~~~~~~~~~~~~~~~^^\n  File \"/Users/kk/Code/whisperforge--prime/core/supabase_integration.py\", line 397, in get_supabase_client\n    _supabase_client = SupabaseClient()\n  File \"/Users/kk/Code/whisperforge--prime/core/supabase_integration.py\", line 38, in __init__\n    self.client: Client = create_client(self.url, self.key)\n                          ~~~~~~~~~~~~~^^^^^^^^^^^^^^^^^^^^\n  File \"/Users/kk/Code/whisperforge--prime/venv/lib/python3.13/site-packages/supabase/_sync/client.py\", line 341, in create_client\n    return SyncClient.create(\n           ~~~~~~~~~~~~~~~~~^\n        supabase_url=supabase_url, supabase_key=supabase_key, options=options\n        ^^^^^^^^^^^^^^^^^^^^^^^^^^^^^^^^^^^^^^^^^^^^^^^^^^^^^^^^^^^^^^^^^^^^^\n    )\n    ^\n  File \"/Users/kk/Code/whisperforge--prime/venv/lib/python3.13/site-packages/supabase/_sync/client.py\", line 103, in create\n    client = cls(supabase_url, supabase_key, options)\n  File \"/Users/kk/Code/whisperforge--prime/venv/lib/python3.13/site-packages/supabase/_sync/client.py\", line 64, in __init__\n    raise SupabaseException(\"Invalid API key\")\nsupabase._sync.client.SupabaseException: Invalid API key\n", "timestamp": "2025-06-11T19:13:27.101000"}
{"event": "error", "error_type": "KeyError", "error_message": "'key_value'", "context": "Failed to load user preferences", "traceback": "Traceback (most recent call last):\n  File \"/Users/kk/Code/whisperforge--prime/core/auth_wrapper.py\", line 183, in _load_user_preferences\n    api_keys[item[\"key_name\"]] = item[\"key_value\"]\n                                 ~~~~^^^^^^^^^^^^^\nKeyError: 'key_value'\n", "timestamp": "2025-06-11T19:13:27.101402"}
{"event": "error", "error_type": "SupabaseException", "error_message": "Invalid API key", "context": "Failed to initialize Supabase", "traceback": "Traceback (most recent call last):\n  File \"/Users/kk/Code/whisperforge--prime/core/auth_wrapper.py\", line 30, in _init_supabase\n    self.supabase_client = get_supabase_client()\n                           ~~~~~~~~~~~~~~~~~~~^^\n  File \"/Users/kk/Code/whisperforge--prime/core/supabase_integration.py\", line 397, in get_supabase_client\n    _supabase_client = SupabaseClient()\n  File \"/Users/kk/Code/whisperforge--prime/core/supabase_integration.py\", line 38, in __init__\n    self.client: Client = create_client(self.url, self.key)\n                          ~~~~~~~~~~~~~^^^^^^^^^^^^^^^^^^^^\n  File \"/Users/kk/Code/whisperforge--prime/venv/lib/python3.13/site-packages/supabase/_sync/client.py\", line 341, in create_client\n    return SyncClient.create(\n           ~~~~~~~~~~~~~~~~~^\n        supabase_url=supabase_url, supabase_key=supabase_key, options=options\n        ^^^^^^^^^^^^^^^^^^^^^^^^^^^^^^^^^^^^^^^^^^^^^^^^^^^^^^^^^^^^^^^^^^^^^\n    )\n    ^\n  File \"/Users/kk/Code/whisperforge--prime/venv/lib/python3.13/site-packages/supabase/_sync/client.py\", line 103, in create\n    client = cls(supabase_url, supabase_key, options)\n  File \"/Users/kk/Code/whisperforge--prime/venv/lib/python3.13/site-packages/supabase/_sync/client.py\", line 64, in __init__\n    raise SupabaseException(\"Invalid API key\")\nsupabase._sync.client.SupabaseException: Invalid API key\n", "timestamp": "2025-06-11T19:13:27.102559"}
{"event": "error", "error_type": "SupabaseException", "error_message": "Invalid API key", "context": "Failed to initialize Supabase", "traceback": "Traceback (most recent call last):\n  File \"/Users/kk/Code/whisperforge--prime/core/auth_wrapper.py\", line 30, in _init_supabase\n    self.supabase_client = get_supabase_client()\n                           ~~~~~~~~~~~~~~~~~~~^^\n  File \"/Users/kk/Code/whisperforge--prime/core/supabase_integration.py\", line 397, in get_supabase_client\n    _supabase_client = SupabaseClient()\n  File \"/Users/kk/Code/whisperforge--prime/core/supabase_integration.py\", line 38, in __init__\n    self.client: Client = create_client(self.url, self.key)\n                          ~~~~~~~~~~~~~^^^^^^^^^^^^^^^^^^^^\n  File \"/Users/kk/Code/whisperforge--prime/venv/lib/python3.13/site-packages/supabase/_sync/client.py\", line 341, in create_client\n    return SyncClient.create(\n           ~~~~~~~~~~~~~~~~~^\n        supabase_url=supabase_url, supabase_key=supabase_key, options=options\n        ^^^^^^^^^^^^^^^^^^^^^^^^^^^^^^^^^^^^^^^^^^^^^^^^^^^^^^^^^^^^^^^^^^^^^\n    )\n    ^\n  File \"/Users/kk/Code/whisperforge--prime/venv/lib/python3.13/site-packages/supabase/_sync/client.py\", line 103, in create\n    client = cls(supabase_url, supabase_key, options)\n  File \"/Users/kk/Code/whisperforge--prime/venv/lib/python3.13/site-packages/supabase/_sync/client.py\", line 64, in __init__\n    raise SupabaseException(\"Invalid API key\")\nsupabase._sync.client.SupabaseException: Invalid API key\n", "timestamp": "2025-06-11T19:13:27.103764"}
{"event": "error", "error_type": "SupabaseException", "error_message": "Invalid API key", "context": "Failed to initialize Supabase", "traceback": "Traceback (most recent call last):\n  File \"/Users/kk/Code/whisperforge--prime/core/auth_wrapper.py\", line 30, in _init_supabase\n    self.supabase_client = get_supabase_client()\n                           ~~~~~~~~~~~~~~~~~~~^^\n  File \"/Users/kk/Code/whisperforge--prime/core/supabase_integration.py\", line 397, in get_supabase_client\n    _supabase_client = SupabaseClient()\n  File \"/Users/kk/Code/whisperforge--prime/core/supabase_integration.py\", line 38, in __init__\n    self.client: Client = create_client(self.url, self.key)\n                          ~~~~~~~~~~~~~^^^^^^^^^^^^^^^^^^^^\n  File \"/Users/kk/Code/whisperforge--prime/venv/lib/python3.13/site-packages/supabase/_sync/client.py\", line 341, in create_client\n    return SyncClient.create(\n           ~~~~~~~~~~~~~~~~~^\n        supabase_url=supabase_url, supabase_key=supabase_key, options=options\n        ^^^^^^^^^^^^^^^^^^^^^^^^^^^^^^^^^^^^^^^^^^^^^^^^^^^^^^^^^^^^^^^^^^^^^\n    )\n    ^\n  File \"/Users/kk/Code/whisperforge--prime/venv/lib/python3.13/site-packages/supabase/_sync/client.py\", line 103, in create\n    client = cls(supabase_url, supabase_key, options)\n  File \"/Users/kk/Code/whisperforge--prime/venv/lib/python3.13/site-packages/supabase/_sync/client.py\", line 64, in __init__\n    raise SupabaseException(\"Invalid API key\")\nsupabase._sync.client.SupabaseException: Invalid API key\n", "timestamp": "2025-06-11T19:13:27.105113"}
{"event": "error", "error_type": "KeyError", "error_message": "'key_value'", "context": "Failed to load user preferences", "traceback": "Traceback (most recent call last):\n  File \"/Users/kk/Code/whisperforge--prime/core/auth_wrapper.py\", line 183, in _load_user_preferences\n    api_keys[item[\"key_name\"]] = item[\"key_value\"]\n                                 ~~~~^^^^^^^^^^^^^\nKeyError: 'key_value'\n", "timestamp": "2025-06-11T19:13:27.105663"}
{"event": "error", "error_type": "SupabaseException", "error_message": "Invalid API key", "context": "Failed to initialize Supabase", "traceback": "Traceback (most recent call last):\n  File \"/Users/kk/Code/whisperforge--prime/core/auth_wrapper.py\", line 30, in _init_supabase\n    self.supabase_client = get_supabase_client()\n                           ~~~~~~~~~~~~~~~~~~~^^\n  File \"/Users/kk/Code/whisperforge--prime/core/supabase_integration.py\", line 397, in get_supabase_client\n    _supabase_client = SupabaseClient()\n  File \"/Users/kk/Code/whisperforge--prime/core/supabase_integration.py\", line 38, in __init__\n    self.client: Client = create_client(self.url, self.key)\n                          ~~~~~~~~~~~~~^^^^^^^^^^^^^^^^^^^^\n  File \"/Users/kk/Code/whisperforge--prime/venv/lib/python3.13/site-packages/supabase/_sync/client.py\", line 341, in create_client\n    return SyncClient.create(\n           ~~~~~~~~~~~~~~~~~^\n        supabase_url=supabase_url, supabase_key=supabase_key, options=options\n        ^^^^^^^^^^^^^^^^^^^^^^^^^^^^^^^^^^^^^^^^^^^^^^^^^^^^^^^^^^^^^^^^^^^^^\n    )\n    ^\n  File \"/Users/kk/Code/whisperforge--prime/venv/lib/python3.13/site-packages/supabase/_sync/client.py\", line 103, in create\n    client = cls(supabase_url, supabase_key, options)\n  File \"/Users/kk/Code/whisperforge--prime/venv/lib/python3.13/site-packages/supabase/_sync/client.py\", line 64, in __init__\n    raise SupabaseException(\"Invalid API key\")\nsupabase._sync.client.SupabaseException: Invalid API key\n", "timestamp": "2025-06-11T19:13:27.106752"}
{"event": "error", "error_type": "SupabaseException", "error_message": "Invalid API key", "context": "Failed to initialize Supabase", "traceback": "Traceback (most recent call last):\n  File \"/Users/kk/Code/whisperforge--prime/core/auth_wrapper.py\", line 30, in _init_supabase\n    self.supabase_client = get_supabase_client()\n                           ~~~~~~~~~~~~~~~~~~~^^\n  File \"/Users/kk/Code/whisperforge--prime/core/supabase_integration.py\", line 397, in get_supabase_client\n    _supabase_client = SupabaseClient()\n  File \"/Users/kk/Code/whisperforge--prime/core/supabase_integration.py\", line 38, in __init__\n    self.client: Client = create_client(self.url, self.key)\n                          ~~~~~~~~~~~~~^^^^^^^^^^^^^^^^^^^^\n  File \"/Users/kk/Code/whisperforge--prime/venv/lib/python3.13/site-packages/supabase/_sync/client.py\", line 341, in create_client\n    return SyncClient.create(\n           ~~~~~~~~~~~~~~~~~^\n        supabase_url=supabase_url, supabase_key=supabase_key, options=options\n        ^^^^^^^^^^^^^^^^^^^^^^^^^^^^^^^^^^^^^^^^^^^^^^^^^^^^^^^^^^^^^^^^^^^^^\n    )\n    ^\n  File \"/Users/kk/Code/whisperforge--prime/venv/lib/python3.13/site-packages/supabase/_sync/client.py\", line 103, in create\n    client = cls(supabase_url, supabase_key, options)\n  File \"/Users/kk/Code/whisperforge--prime/venv/lib/python3.13/site-packages/supabase/_sync/client.py\", line 64, in __init__\n    raise SupabaseException(\"Invalid API key\")\nsupabase._sync.client.SupabaseException: Invalid API key\n", "timestamp": "2025-06-11T19:13:27.107943"}
{"step": "test_step", "status": "started", "timestamp": "2025-06-11T19:13:48.788761", "data": {}}
{"step": "test_step", "status": "completed", "timestamp": "2025-06-11T19:13:48.789196", "data": {}}
{"step": "test_step", "status": "failed", "timestamp": "2025-06-11T19:13:48.789276", "data": {"error": "Test error"}}
{"event": "file_upload", "filename": "test.wav", "size_mb": 1.5, "file_type": "audio/wav", "timestamp": "2025-06-11T19:13:48.789553"}
{"event": "error", "error_type": "ValueError", "error_message": "Test error", "context": "Test context", "traceback": "Traceback (most recent call last):\n  File \"/Users/kk/Code/whisperforge--prime/tests/test_basic_functionality.py\", line 32, in test_logging_functionality\n    raise ValueError(\"Test error\")\nValueError: Test error\n", "timestamp": "2025-06-11T19:13:48.790114"}
{"event": "error", "error_type": "ValueError", "error_message": "Test error for logging", "context": "Test error context", "traceback": "Traceback (most recent call last):\n  File \"/Users/kk/Code/whisperforge--prime/tests/test_basic_functionality.py\", line 167, in test_logging_error_handling\n    raise ValueError(\"Test error for logging\")\nValueError: Test error for logging\n", "timestamp": "2025-06-11T19:13:48.928117"}
{"event": "error", "error_type": "ValueError", "error_message": "SUPABASE_URL and SUPABASE_ANON_KEY must be set in environment variables", "context": "Failed to initialize Supabase", "traceback": "Traceback (most recent call last):\n  File \"/Users/kk/Code/whisperforge--prime/core/auth_wrapper.py\", line 30, in _init_supabase\n    self.supabase_client = get_supabase_client()\n                           ~~~~~~~~~~~~~~~~~~~^^\n  File \"/Users/kk/Code/whisperforge--prime/core/supabase_integration.py\", line 397, in get_supabase_client\n    _supabase_client = SupabaseClient()\n  File \"/Users/kk/Code/whisperforge--prime/core/supabase_integration.py\", line 36, in __init__\n    raise ValueError(\"SUPABASE_URL and SUPABASE_ANON_KEY must be set in environment variables\")\nValueError: SUPABASE_URL and SUPABASE_ANON_KEY must be set in environment variables\n", "timestamp": "2025-06-11T19:13:48.937026"}
{"event": "error", "error_type": "ValueError", "error_message": "SUPABASE_URL and SUPABASE_ANON_KEY must be set in environment variables", "context": "Failed to initialize Supabase", "traceback": "Traceback (most recent call last):\n  File \"/Users/kk/Code/whisperforge--prime/core/auth_wrapper.py\", line 30, in _init_supabase\n    self.supabase_client = get_supabase_client()\n                           ~~~~~~~~~~~~~~~~~~~^^\n  File \"/Users/kk/Code/whisperforge--prime/core/supabase_integration.py\", line 397, in get_supabase_client\n    _supabase_client = SupabaseClient()\n  File \"/Users/kk/Code/whisperforge--prime/core/supabase_integration.py\", line 36, in __init__\n    raise ValueError(\"SUPABASE_URL and SUPABASE_ANON_KEY must be set in environment variables\")\nValueError: SUPABASE_URL and SUPABASE_ANON_KEY must be set in environment variables\n", "timestamp": "2025-06-11T19:13:48.938597"}
{"event": "error", "error_type": "ValueError", "error_message": "SUPABASE_URL and SUPABASE_ANON_KEY must be set in environment variables", "context": "Failed to initialize Supabase", "traceback": "Traceback (most recent call last):\n  File \"/Users/kk/Code/whisperforge--prime/core/auth_wrapper.py\", line 30, in _init_supabase\n    self.supabase_client = get_supabase_client()\n                           ~~~~~~~~~~~~~~~~~~~^^\n  File \"/Users/kk/Code/whisperforge--prime/core/supabase_integration.py\", line 397, in get_supabase_client\n    _supabase_client = SupabaseClient()\n  File \"/Users/kk/Code/whisperforge--prime/core/supabase_integration.py\", line 36, in __init__\n    raise ValueError(\"SUPABASE_URL and SUPABASE_ANON_KEY must be set in environment variables\")\nValueError: SUPABASE_URL and SUPABASE_ANON_KEY must be set in environment variables\n", "timestamp": "2025-06-11T19:13:48.939762"}
{"step": "test_step", "status": "started", "timestamp": "2025-06-11T19:13:58.198531", "data": {}}
{"step": "test_step", "status": "completed", "timestamp": "2025-06-11T19:13:58.198736", "data": {}}
{"step": "test_step", "status": "failed", "timestamp": "2025-06-11T19:13:58.199019", "data": {"error": "Test error"}}
{"event": "file_upload", "filename": "test.wav", "size_mb": 1.5, "file_type": "audio/wav", "timestamp": "2025-06-11T19:13:58.199272"}
{"event": "error", "error_type": "ValueError", "error_message": "Test error", "context": "Test context", "traceback": "Traceback (most recent call last):\n  File \"/Users/kk/Code/whisperforge--prime/tests/test_basic_functionality.py\", line 32, in test_logging_functionality\n    raise ValueError(\"Test error\")\nValueError: Test error\n", "timestamp": "2025-06-11T19:13:58.199813"}
{"event": "error", "error_type": "ValueError", "error_message": "Test error for logging", "context": "Test error context", "traceback": "Traceback (most recent call last):\n  File \"/Users/kk/Code/whisperforge--prime/tests/test_basic_functionality.py\", line 167, in test_logging_error_handling\n    raise ValueError(\"Test error for logging\")\nValueError: Test error for logging\n", "timestamp": "2025-06-11T19:13:58.297242"}
{"event": "error", "error_type": "SupabaseException", "error_message": "Invalid API key", "context": "Failed to initialize Supabase", "traceback": "Traceback (most recent call last):\n  File \"/Users/kk/Code/whisperforge--prime/core/auth_wrapper.py\", line 30, in _init_supabase\n    self.supabase_client = get_supabase_client()\n                           ~~~~~~~~~~~~~~~~~~~^^\n  File \"/Users/kk/Code/whisperforge--prime/core/supabase_integration.py\", line 397, in get_supabase_client\n    _supabase_client = SupabaseClient()\n  File \"/Users/kk/Code/whisperforge--prime/core/supabase_integration.py\", line 38, in __init__\n    self.client: Client = create_client(self.url, self.key)\n                          ~~~~~~~~~~~~~^^^^^^^^^^^^^^^^^^^^\n  File \"/Users/kk/Code/whisperforge--prime/venv/lib/python3.13/site-packages/supabase/_sync/client.py\", line 341, in create_client\n    return SyncClient.create(\n           ~~~~~~~~~~~~~~~~~^\n        supabase_url=supabase_url, supabase_key=supabase_key, options=options\n        ^^^^^^^^^^^^^^^^^^^^^^^^^^^^^^^^^^^^^^^^^^^^^^^^^^^^^^^^^^^^^^^^^^^^^\n    )\n    ^\n  File \"/Users/kk/Code/whisperforge--prime/venv/lib/python3.13/site-packages/supabase/_sync/client.py\", line 103, in create\n    client = cls(supabase_url, supabase_key, options)\n  File \"/Users/kk/Code/whisperforge--prime/venv/lib/python3.13/site-packages/supabase/_sync/client.py\", line 64, in __init__\n    raise SupabaseException(\"Invalid API key\")\nsupabase._sync.client.SupabaseException: Invalid API key\n", "timestamp": "2025-06-11T19:13:58.305832"}
{"event": "error", "error_type": "SupabaseException", "error_message": "Invalid API key", "context": "Failed to initialize Supabase", "traceback": "Traceback (most recent call last):\n  File \"/Users/kk/Code/whisperforge--prime/core/auth_wrapper.py\", line 30, in _init_supabase\n    self.supabase_client = get_supabase_client()\n                           ~~~~~~~~~~~~~~~~~~~^^\n  File \"/Users/kk/Code/whisperforge--prime/core/supabase_integration.py\", line 397, in get_supabase_client\n    _supabase_client = SupabaseClient()\n  File \"/Users/kk/Code/whisperforge--prime/core/supabase_integration.py\", line 38, in __init__\n    self.client: Client = create_client(self.url, self.key)\n                          ~~~~~~~~~~~~~^^^^^^^^^^^^^^^^^^^^\n  File \"/Users/kk/Code/whisperforge--prime/venv/lib/python3.13/site-packages/supabase/_sync/client.py\", line 341, in create_client\n    return SyncClient.create(\n           ~~~~~~~~~~~~~~~~~^\n        supabase_url=supabase_url, supabase_key=supabase_key, options=options\n        ^^^^^^^^^^^^^^^^^^^^^^^^^^^^^^^^^^^^^^^^^^^^^^^^^^^^^^^^^^^^^^^^^^^^^\n    )\n    ^\n  File \"/Users/kk/Code/whisperforge--prime/venv/lib/python3.13/site-packages/supabase/_sync/client.py\", line 103, in create\n    client = cls(supabase_url, supabase_key, options)\n  File \"/Users/kk/Code/whisperforge--prime/venv/lib/python3.13/site-packages/supabase/_sync/client.py\", line 64, in __init__\n    raise SupabaseException(\"Invalid API key\")\nsupabase._sync.client.SupabaseException: Invalid API key\n", "timestamp": "2025-06-11T19:13:58.307149"}
{"event": "error", "error_type": "KeyError", "error_message": "'key_value'", "context": "Failed to load user preferences", "traceback": "Traceback (most recent call last):\n  File \"/Users/kk/Code/whisperforge--prime/core/auth_wrapper.py\", line 183, in _load_user_preferences\n    api_keys[item[\"key_name\"]] = item[\"key_value\"]\n                                 ~~~~^^^^^^^^^^^^^\nKeyError: 'key_value'\n", "timestamp": "2025-06-11T19:13:58.307581"}
{"event": "error", "error_type": "SupabaseException", "error_message": "Invalid API key", "context": "Failed to initialize Supabase", "traceback": "Traceback (most recent call last):\n  File \"/Users/kk/Code/whisperforge--prime/core/auth_wrapper.py\", line 30, in _init_supabase\n    self.supabase_client = get_supabase_client()\n                           ~~~~~~~~~~~~~~~~~~~^^\n  File \"/Users/kk/Code/whisperforge--prime/core/supabase_integration.py\", line 397, in get_supabase_client\n    _supabase_client = SupabaseClient()\n  File \"/Users/kk/Code/whisperforge--prime/core/supabase_integration.py\", line 38, in __init__\n    self.client: Client = create_client(self.url, self.key)\n                          ~~~~~~~~~~~~~^^^^^^^^^^^^^^^^^^^^\n  File \"/Users/kk/Code/whisperforge--prime/venv/lib/python3.13/site-packages/supabase/_sync/client.py\", line 341, in create_client\n    return SyncClient.create(\n           ~~~~~~~~~~~~~~~~~^\n        supabase_url=supabase_url, supabase_key=supabase_key, options=options\n        ^^^^^^^^^^^^^^^^^^^^^^^^^^^^^^^^^^^^^^^^^^^^^^^^^^^^^^^^^^^^^^^^^^^^^\n    )\n    ^\n  File \"/Users/kk/Code/whisperforge--prime/venv/lib/python3.13/site-packages/supabase/_sync/client.py\", line 103, in create\n    client = cls(supabase_url, supabase_key, options)\n  File \"/Users/kk/Code/whisperforge--prime/venv/lib/python3.13/site-packages/supabase/_sync/client.py\", line 64, in __init__\n    raise SupabaseException(\"Invalid API key\")\nsupabase._sync.client.SupabaseException: Invalid API key\n", "timestamp": "2025-06-11T19:13:58.308888"}
{"event": "error", "error_type": "SupabaseException", "error_message": "Invalid API key", "context": "Failed to initialize Supabase", "traceback": "Traceback (most recent call last):\n  File \"/Users/kk/Code/whisperforge--prime/core/auth_wrapper.py\", line 30, in _init_supabase\n    self.supabase_client = get_supabase_client()\n                           ~~~~~~~~~~~~~~~~~~~^^\n  File \"/Users/kk/Code/whisperforge--prime/core/supabase_integration.py\", line 397, in get_supabase_client\n    _supabase_client = SupabaseClient()\n  File \"/Users/kk/Code/whisperforge--prime/core/supabase_integration.py\", line 38, in __init__\n    self.client: Client = create_client(self.url, self.key)\n                          ~~~~~~~~~~~~~^^^^^^^^^^^^^^^^^^^^\n  File \"/Users/kk/Code/whisperforge--prime/venv/lib/python3.13/site-packages/supabase/_sync/client.py\", line 341, in create_client\n    return SyncClient.create(\n           ~~~~~~~~~~~~~~~~~^\n        supabase_url=supabase_url, supabase_key=supabase_key, options=options\n        ^^^^^^^^^^^^^^^^^^^^^^^^^^^^^^^^^^^^^^^^^^^^^^^^^^^^^^^^^^^^^^^^^^^^^\n    )\n    ^\n  File \"/Users/kk/Code/whisperforge--prime/venv/lib/python3.13/site-packages/supabase/_sync/client.py\", line 103, in create\n    client = cls(supabase_url, supabase_key, options)\n  File \"/Users/kk/Code/whisperforge--prime/venv/lib/python3.13/site-packages/supabase/_sync/client.py\", line 64, in __init__\n    raise SupabaseException(\"Invalid API key\")\nsupabase._sync.client.SupabaseException: Invalid API key\n", "timestamp": "2025-06-11T19:13:58.310099"}
{"event": "error", "error_type": "SupabaseException", "error_message": "Invalid API key", "context": "Failed to initialize Supabase", "traceback": "Traceback (most recent call last):\n  File \"/Users/kk/Code/whisperforge--prime/core/auth_wrapper.py\", line 30, in _init_supabase\n    self.supabase_client = get_supabase_client()\n                           ~~~~~~~~~~~~~~~~~~~^^\n  File \"/Users/kk/Code/whisperforge--prime/core/supabase_integration.py\", line 397, in get_supabase_client\n    _supabase_client = SupabaseClient()\n  File \"/Users/kk/Code/whisperforge--prime/core/supabase_integration.py\", line 38, in __init__\n    self.client: Client = create_client(self.url, self.key)\n                          ~~~~~~~~~~~~~^^^^^^^^^^^^^^^^^^^^\n  File \"/Users/kk/Code/whisperforge--prime/venv/lib/python3.13/site-packages/supabase/_sync/client.py\", line 341, in create_client\n    return SyncClient.create(\n           ~~~~~~~~~~~~~~~~~^\n        supabase_url=supabase_url, supabase_key=supabase_key, options=options\n        ^^^^^^^^^^^^^^^^^^^^^^^^^^^^^^^^^^^^^^^^^^^^^^^^^^^^^^^^^^^^^^^^^^^^^\n    )\n    ^\n  File \"/Users/kk/Code/whisperforge--prime/venv/lib/python3.13/site-packages/supabase/_sync/client.py\", line 103, in create\n    client = cls(supabase_url, supabase_key, options)\n  File \"/Users/kk/Code/whisperforge--prime/venv/lib/python3.13/site-packages/supabase/_sync/client.py\", line 64, in __init__\n    raise SupabaseException(\"Invalid API key\")\nsupabase._sync.client.SupabaseException: Invalid API key\n", "timestamp": "2025-06-11T19:13:58.311404"}
{"event": "error", "error_type": "KeyError", "error_message": "'key_value'", "context": "Failed to load user preferences", "traceback": "Traceback (most recent call last):\n  File \"/Users/kk/Code/whisperforge--prime/core/auth_wrapper.py\", line 183, in _load_user_preferences\n    api_keys[item[\"key_name\"]] = item[\"key_value\"]\n                                 ~~~~^^^^^^^^^^^^^\nKeyError: 'key_value'\n", "timestamp": "2025-06-11T19:13:58.311861"}
{"event": "error", "error_type": "SupabaseException", "error_message": "Invalid API key", "context": "Failed to initialize Supabase", "traceback": "Traceback (most recent call last):\n  File \"/Users/kk/Code/whisperforge--prime/core/auth_wrapper.py\", line 30, in _init_supabase\n    self.supabase_client = get_supabase_client()\n                           ~~~~~~~~~~~~~~~~~~~^^\n  File \"/Users/kk/Code/whisperforge--prime/core/supabase_integration.py\", line 397, in get_supabase_client\n    _supabase_client = SupabaseClient()\n  File \"/Users/kk/Code/whisperforge--prime/core/supabase_integration.py\", line 38, in __init__\n    self.client: Client = create_client(self.url, self.key)\n                          ~~~~~~~~~~~~~^^^^^^^^^^^^^^^^^^^^\n  File \"/Users/kk/Code/whisperforge--prime/venv/lib/python3.13/site-packages/supabase/_sync/client.py\", line 341, in create_client\n    return SyncClient.create(\n           ~~~~~~~~~~~~~~~~~^\n        supabase_url=supabase_url, supabase_key=supabase_key, options=options\n        ^^^^^^^^^^^^^^^^^^^^^^^^^^^^^^^^^^^^^^^^^^^^^^^^^^^^^^^^^^^^^^^^^^^^^\n    )\n    ^\n  File \"/Users/kk/Code/whisperforge--prime/venv/lib/python3.13/site-packages/supabase/_sync/client.py\", line 103, in create\n    client = cls(supabase_url, supabase_key, options)\n  File \"/Users/kk/Code/whisperforge--prime/venv/lib/python3.13/site-packages/supabase/_sync/client.py\", line 64, in __init__\n    raise SupabaseException(\"Invalid API key\")\nsupabase._sync.client.SupabaseException: Invalid API key\n", "timestamp": "2025-06-11T19:13:58.313029"}
{"event": "error", "error_type": "SupabaseException", "error_message": "Invalid API key", "context": "Failed to initialize Supabase", "traceback": "Traceback (most recent call last):\n  File \"/Users/kk/Code/whisperforge--prime/core/auth_wrapper.py\", line 30, in _init_supabase\n    self.supabase_client = get_supabase_client()\n                           ~~~~~~~~~~~~~~~~~~~^^\n  File \"/Users/kk/Code/whisperforge--prime/core/supabase_integration.py\", line 397, in get_supabase_client\n    _supabase_client = SupabaseClient()\n  File \"/Users/kk/Code/whisperforge--prime/core/supabase_integration.py\", line 38, in __init__\n    self.client: Client = create_client(self.url, self.key)\n                          ~~~~~~~~~~~~~^^^^^^^^^^^^^^^^^^^^\n  File \"/Users/kk/Code/whisperforge--prime/venv/lib/python3.13/site-packages/supabase/_sync/client.py\", line 341, in create_client\n    return SyncClient.create(\n           ~~~~~~~~~~~~~~~~~^\n        supabase_url=supabase_url, supabase_key=supabase_key, options=options\n        ^^^^^^^^^^^^^^^^^^^^^^^^^^^^^^^^^^^^^^^^^^^^^^^^^^^^^^^^^^^^^^^^^^^^^\n    )\n    ^\n  File \"/Users/kk/Code/whisperforge--prime/venv/lib/python3.13/site-packages/supabase/_sync/client.py\", line 103, in create\n    client = cls(supabase_url, supabase_key, options)\n  File \"/Users/kk/Code/whisperforge--prime/venv/lib/python3.13/site-packages/supabase/_sync/client.py\", line 64, in __init__\n    raise SupabaseException(\"Invalid API key\")\nsupabase._sync.client.SupabaseException: Invalid API key\n", "timestamp": "2025-06-11T19:13:58.314434"}
{"step": "test_step", "status": "started", "timestamp": "2025-06-11T19:15:55.542501", "data": {}}
{"step": "test_step", "status": "completed", "timestamp": "2025-06-11T19:15:55.542870", "data": {}}
{"step": "test_step", "status": "failed", "timestamp": "2025-06-11T19:15:55.542955", "data": {"error": "Test error"}}
{"event": "file_upload", "filename": "test.wav", "size_mb": 1.5, "file_type": "audio/wav", "timestamp": "2025-06-11T19:15:55.543096"}
{"event": "error", "error_type": "ValueError", "error_message": "Test error", "context": "Test context", "traceback": "Traceback (most recent call last):\n  File \"/Users/kk/Code/whisperforge--prime/tests/test_basic_functionality.py\", line 32, in test_logging_functionality\n    raise ValueError(\"Test error\")\nValueError: Test error\n", "timestamp": "2025-06-11T19:15:55.543772"}
{"event": "error", "error_type": "ValueError", "error_message": "Test error for logging", "context": "Test error context", "traceback": "Traceback (most recent call last):\n  File \"/Users/kk/Code/whisperforge--prime/tests/test_basic_functionality.py\", line 167, in test_logging_error_handling\n    raise ValueError(\"Test error for logging\")\nValueError: Test error for logging\n", "timestamp": "2025-06-11T19:15:55.690215"}
{"event": "error", "error_type": "SupabaseException", "error_message": "Invalid API key", "context": "Failed to initialize Supabase", "traceback": "Traceback (most recent call last):\n  File \"/Users/kk/Code/whisperforge--prime/core/auth_wrapper.py\", line 30, in _init_supabase\n    self.supabase_client = get_supabase_client()\n                           ~~~~~~~~~~~~~~~~~~~^^\n  File \"/Users/kk/Code/whisperforge--prime/core/supabase_integration.py\", line 397, in get_supabase_client\n    _supabase_client = SupabaseClient()\n  File \"/Users/kk/Code/whisperforge--prime/core/supabase_integration.py\", line 38, in __init__\n    self.client: Client = create_client(self.url, self.key)\n                          ~~~~~~~~~~~~~^^^^^^^^^^^^^^^^^^^^\n  File \"/Users/kk/Code/whisperforge--prime/venv/lib/python3.13/site-packages/supabase/_sync/client.py\", line 341, in create_client\n    return SyncClient.create(\n           ~~~~~~~~~~~~~~~~~^\n        supabase_url=supabase_url, supabase_key=supabase_key, options=options\n        ^^^^^^^^^^^^^^^^^^^^^^^^^^^^^^^^^^^^^^^^^^^^^^^^^^^^^^^^^^^^^^^^^^^^^\n    )\n    ^\n  File \"/Users/kk/Code/whisperforge--prime/venv/lib/python3.13/site-packages/supabase/_sync/client.py\", line 103, in create\n    client = cls(supabase_url, supabase_key, options)\n  File \"/Users/kk/Code/whisperforge--prime/venv/lib/python3.13/site-packages/supabase/_sync/client.py\", line 64, in __init__\n    raise SupabaseException(\"Invalid API key\")\nsupabase._sync.client.SupabaseException: Invalid API key\n", "timestamp": "2025-06-11T19:15:55.699583"}
{"event": "error", "error_type": "SupabaseException", "error_message": "Invalid API key", "context": "Failed to initialize Supabase", "traceback": "Traceback (most recent call last):\n  File \"/Users/kk/Code/whisperforge--prime/core/auth_wrapper.py\", line 30, in _init_supabase\n    self.supabase_client = get_supabase_client()\n                           ~~~~~~~~~~~~~~~~~~~^^\n  File \"/Users/kk/Code/whisperforge--prime/core/supabase_integration.py\", line 397, in get_supabase_client\n    _supabase_client = SupabaseClient()\n  File \"/Users/kk/Code/whisperforge--prime/core/supabase_integration.py\", line 38, in __init__\n    self.client: Client = create_client(self.url, self.key)\n                          ~~~~~~~~~~~~~^^^^^^^^^^^^^^^^^^^^\n  File \"/Users/kk/Code/whisperforge--prime/venv/lib/python3.13/site-packages/supabase/_sync/client.py\", line 341, in create_client\n    return SyncClient.create(\n           ~~~~~~~~~~~~~~~~~^\n        supabase_url=supabase_url, supabase_key=supabase_key, options=options\n        ^^^^^^^^^^^^^^^^^^^^^^^^^^^^^^^^^^^^^^^^^^^^^^^^^^^^^^^^^^^^^^^^^^^^^\n    )\n    ^\n  File \"/Users/kk/Code/whisperforge--prime/venv/lib/python3.13/site-packages/supabase/_sync/client.py\", line 103, in create\n    client = cls(supabase_url, supabase_key, options)\n  File \"/Users/kk/Code/whisperforge--prime/venv/lib/python3.13/site-packages/supabase/_sync/client.py\", line 64, in __init__\n    raise SupabaseException(\"Invalid API key\")\nsupabase._sync.client.SupabaseException: Invalid API key\n", "timestamp": "2025-06-11T19:15:55.700911"}
{"event": "error", "error_type": "KeyError", "error_message": "'key_value'", "context": "Failed to load user preferences", "traceback": "Traceback (most recent call last):\n  File \"/Users/kk/Code/whisperforge--prime/core/auth_wrapper.py\", line 183, in _load_user_preferences\n    api_keys[item[\"key_name\"]] = item[\"key_value\"]\n                                 ~~~~^^^^^^^^^^^^^\nKeyError: 'key_value'\n", "timestamp": "2025-06-11T19:15:55.701365"}
{"event": "error", "error_type": "SupabaseException", "error_message": "Invalid API key", "context": "Failed to initialize Supabase", "traceback": "Traceback (most recent call last):\n  File \"/Users/kk/Code/whisperforge--prime/core/auth_wrapper.py\", line 30, in _init_supabase\n    self.supabase_client = get_supabase_client()\n                           ~~~~~~~~~~~~~~~~~~~^^\n  File \"/Users/kk/Code/whisperforge--prime/core/supabase_integration.py\", line 397, in get_supabase_client\n    _supabase_client = SupabaseClient()\n  File \"/Users/kk/Code/whisperforge--prime/core/supabase_integration.py\", line 38, in __init__\n    self.client: Client = create_client(self.url, self.key)\n                          ~~~~~~~~~~~~~^^^^^^^^^^^^^^^^^^^^\n  File \"/Users/kk/Code/whisperforge--prime/venv/lib/python3.13/site-packages/supabase/_sync/client.py\", line 341, in create_client\n    return SyncClient.create(\n           ~~~~~~~~~~~~~~~~~^\n        supabase_url=supabase_url, supabase_key=supabase_key, options=options\n        ^^^^^^^^^^^^^^^^^^^^^^^^^^^^^^^^^^^^^^^^^^^^^^^^^^^^^^^^^^^^^^^^^^^^^\n    )\n    ^\n  File \"/Users/kk/Code/whisperforge--prime/venv/lib/python3.13/site-packages/supabase/_sync/client.py\", line 103, in create\n    client = cls(supabase_url, supabase_key, options)\n  File \"/Users/kk/Code/whisperforge--prime/venv/lib/python3.13/site-packages/supabase/_sync/client.py\", line 64, in __init__\n    raise SupabaseException(\"Invalid API key\")\nsupabase._sync.client.SupabaseException: Invalid API key\n", "timestamp": "2025-06-11T19:15:55.702835"}
{"event": "error", "error_type": "SupabaseException", "error_message": "Invalid API key", "context": "Failed to initialize Supabase", "traceback": "Traceback (most recent call last):\n  File \"/Users/kk/Code/whisperforge--prime/core/auth_wrapper.py\", line 30, in _init_supabase\n    self.supabase_client = get_supabase_client()\n                           ~~~~~~~~~~~~~~~~~~~^^\n  File \"/Users/kk/Code/whisperforge--prime/core/supabase_integration.py\", line 397, in get_supabase_client\n    _supabase_client = SupabaseClient()\n  File \"/Users/kk/Code/whisperforge--prime/core/supabase_integration.py\", line 38, in __init__\n    self.client: Client = create_client(self.url, self.key)\n                          ~~~~~~~~~~~~~^^^^^^^^^^^^^^^^^^^^\n  File \"/Users/kk/Code/whisperforge--prime/venv/lib/python3.13/site-packages/supabase/_sync/client.py\", line 341, in create_client\n    return SyncClient.create(\n           ~~~~~~~~~~~~~~~~~^\n        supabase_url=supabase_url, supabase_key=supabase_key, options=options\n        ^^^^^^^^^^^^^^^^^^^^^^^^^^^^^^^^^^^^^^^^^^^^^^^^^^^^^^^^^^^^^^^^^^^^^\n    )\n    ^\n  File \"/Users/kk/Code/whisperforge--prime/venv/lib/python3.13/site-packages/supabase/_sync/client.py\", line 103, in create\n    client = cls(supabase_url, supabase_key, options)\n  File \"/Users/kk/Code/whisperforge--prime/venv/lib/python3.13/site-packages/supabase/_sync/client.py\", line 64, in __init__\n    raise SupabaseException(\"Invalid API key\")\nsupabase._sync.client.SupabaseException: Invalid API key\n", "timestamp": "2025-06-11T19:15:55.704202"}
{"event": "error", "error_type": "SupabaseException", "error_message": "Invalid API key", "context": "Failed to initialize Supabase", "traceback": "Traceback (most recent call last):\n  File \"/Users/kk/Code/whisperforge--prime/core/auth_wrapper.py\", line 30, in _init_supabase\n    self.supabase_client = get_supabase_client()\n                           ~~~~~~~~~~~~~~~~~~~^^\n  File \"/Users/kk/Code/whisperforge--prime/core/supabase_integration.py\", line 397, in get_supabase_client\n    _supabase_client = SupabaseClient()\n  File \"/Users/kk/Code/whisperforge--prime/core/supabase_integration.py\", line 38, in __init__\n    self.client: Client = create_client(self.url, self.key)\n                          ~~~~~~~~~~~~~^^^^^^^^^^^^^^^^^^^^\n  File \"/Users/kk/Code/whisperforge--prime/venv/lib/python3.13/site-packages/supabase/_sync/client.py\", line 341, in create_client\n    return SyncClient.create(\n           ~~~~~~~~~~~~~~~~~^\n        supabase_url=supabase_url, supabase_key=supabase_key, options=options\n        ^^^^^^^^^^^^^^^^^^^^^^^^^^^^^^^^^^^^^^^^^^^^^^^^^^^^^^^^^^^^^^^^^^^^^\n    )\n    ^\n  File \"/Users/kk/Code/whisperforge--prime/venv/lib/python3.13/site-packages/supabase/_sync/client.py\", line 103, in create\n    client = cls(supabase_url, supabase_key, options)\n  File \"/Users/kk/Code/whisperforge--prime/venv/lib/python3.13/site-packages/supabase/_sync/client.py\", line 64, in __init__\n    raise SupabaseException(\"Invalid API key\")\nsupabase._sync.client.SupabaseException: Invalid API key\n", "timestamp": "2025-06-11T19:15:55.705603"}
{"event": "error", "error_type": "KeyError", "error_message": "'key_value'", "context": "Failed to load user preferences", "traceback": "Traceback (most recent call last):\n  File \"/Users/kk/Code/whisperforge--prime/core/auth_wrapper.py\", line 183, in _load_user_preferences\n    api_keys[item[\"key_name\"]] = item[\"key_value\"]\n                                 ~~~~^^^^^^^^^^^^^\nKeyError: 'key_value'\n", "timestamp": "2025-06-11T19:15:55.706088"}
{"event": "error", "error_type": "SupabaseException", "error_message": "Invalid API key", "context": "Failed to initialize Supabase", "traceback": "Traceback (most recent call last):\n  File \"/Users/kk/Code/whisperforge--prime/core/auth_wrapper.py\", line 30, in _init_supabase\n    self.supabase_client = get_supabase_client()\n                           ~~~~~~~~~~~~~~~~~~~^^\n  File \"/Users/kk/Code/whisperforge--prime/core/supabase_integration.py\", line 397, in get_supabase_client\n    _supabase_client = SupabaseClient()\n  File \"/Users/kk/Code/whisperforge--prime/core/supabase_integration.py\", line 38, in __init__\n    self.client: Client = create_client(self.url, self.key)\n                          ~~~~~~~~~~~~~^^^^^^^^^^^^^^^^^^^^\n  File \"/Users/kk/Code/whisperforge--prime/venv/lib/python3.13/site-packages/supabase/_sync/client.py\", line 341, in create_client\n    return SyncClient.create(\n           ~~~~~~~~~~~~~~~~~^\n        supabase_url=supabase_url, supabase_key=supabase_key, options=options\n        ^^^^^^^^^^^^^^^^^^^^^^^^^^^^^^^^^^^^^^^^^^^^^^^^^^^^^^^^^^^^^^^^^^^^^\n    )\n    ^\n  File \"/Users/kk/Code/whisperforge--prime/venv/lib/python3.13/site-packages/supabase/_sync/client.py\", line 103, in create\n    client = cls(supabase_url, supabase_key, options)\n  File \"/Users/kk/Code/whisperforge--prime/venv/lib/python3.13/site-packages/supabase/_sync/client.py\", line 64, in __init__\n    raise SupabaseException(\"Invalid API key\")\nsupabase._sync.client.SupabaseException: Invalid API key\n", "timestamp": "2025-06-11T19:15:55.707310"}
{"event": "error", "error_type": "SupabaseException", "error_message": "Invalid API key", "context": "Failed to initialize Supabase", "traceback": "Traceback (most recent call last):\n  File \"/Users/kk/Code/whisperforge--prime/core/auth_wrapper.py\", line 30, in _init_supabase\n    self.supabase_client = get_supabase_client()\n                           ~~~~~~~~~~~~~~~~~~~^^\n  File \"/Users/kk/Code/whisperforge--prime/core/supabase_integration.py\", line 397, in get_supabase_client\n    _supabase_client = SupabaseClient()\n  File \"/Users/kk/Code/whisperforge--prime/core/supabase_integration.py\", line 38, in __init__\n    self.client: Client = create_client(self.url, self.key)\n                          ~~~~~~~~~~~~~^^^^^^^^^^^^^^^^^^^^\n  File \"/Users/kk/Code/whisperforge--prime/venv/lib/python3.13/site-packages/supabase/_sync/client.py\", line 341, in create_client\n    return SyncClient.create(\n           ~~~~~~~~~~~~~~~~~^\n        supabase_url=supabase_url, supabase_key=supabase_key, options=options\n        ^^^^^^^^^^^^^^^^^^^^^^^^^^^^^^^^^^^^^^^^^^^^^^^^^^^^^^^^^^^^^^^^^^^^^\n    )\n    ^\n  File \"/Users/kk/Code/whisperforge--prime/venv/lib/python3.13/site-packages/supabase/_sync/client.py\", line 103, in create\n    client = cls(supabase_url, supabase_key, options)\n  File \"/Users/kk/Code/whisperforge--prime/venv/lib/python3.13/site-packages/supabase/_sync/client.py\", line 64, in __init__\n    raise SupabaseException(\"Invalid API key\")\nsupabase._sync.client.SupabaseException: Invalid API key\n", "timestamp": "2025-06-11T19:15:55.708720"}
{"step": "test_step", "status": "started", "timestamp": "2025-06-11T19:19:04.400291", "data": {}}
{"step": "test_step", "status": "completed", "timestamp": "2025-06-11T19:19:04.400706", "data": {}}
{"step": "test_step", "status": "failed", "timestamp": "2025-06-11T19:19:04.400792", "data": {"error": "Test error"}}
{"event": "file_upload", "filename": "test.wav", "size_mb": 1.5, "file_type": "audio/wav", "timestamp": "2025-06-11T19:19:04.400934"}
{"event": "error", "error_type": "ValueError", "error_message": "Test error", "context": "Test context", "traceback": "Traceback (most recent call last):\n  File \"/Users/kk/Code/whisperforge--prime/tests/test_basic_functionality.py\", line 32, in test_logging_functionality\n    raise ValueError(\"Test error\")\nValueError: Test error\n", "timestamp": "2025-06-11T19:19:04.401678"}
{"event": "error", "error_type": "ValueError", "error_message": "Test error for logging", "context": "Test error context", "traceback": "Traceback (most recent call last):\n  File \"/Users/kk/Code/whisperforge--prime/tests/test_basic_functionality.py\", line 167, in test_logging_error_handling\n    raise ValueError(\"Test error for logging\")\nValueError: Test error for logging\n", "timestamp": "2025-06-11T19:19:04.558008"}
{"event": "error", "error_type": "KeyError", "error_message": "'key_value'", "context": "Failed to load user preferences", "traceback": "Traceback (most recent call last):\n  File \"/Users/kk/Code/whisperforge--prime/core/auth_wrapper.py\", line 183, in _load_user_preferences\n    api_keys[item[\"key_name\"]] = item[\"key_value\"]\n                                 ~~~~^^^^^^^^^^^^^\nKeyError: 'key_value'\n", "timestamp": "2025-06-11T19:19:04.569135"}
{"event": "error", "error_type": "KeyError", "error_message": "'key_value'", "context": "Failed to load user preferences", "traceback": "Traceback (most recent call last):\n  File \"/Users/kk/Code/whisperforge--prime/core/auth_wrapper.py\", line 183, in _load_user_preferences\n    api_keys[item[\"key_name\"]] = item[\"key_value\"]\n                                 ~~~~^^^^^^^^^^^^^\nKeyError: 'key_value'\n", "timestamp": "2025-06-11T19:19:04.571561"}
{"step": "test_step", "status": "started", "timestamp": "2025-06-11T19:23:22.943602", "data": {}}
{"step": "test_step", "status": "completed", "timestamp": "2025-06-11T19:23:22.944066", "data": {}}
{"step": "test_step", "status": "failed", "timestamp": "2025-06-11T19:23:22.944188", "data": {"error": "Test error"}}
{"event": "file_upload", "filename": "test.wav", "size_mb": 1.5, "file_type": "audio/wav", "timestamp": "2025-06-11T19:23:22.944439"}
{"event": "error", "error_type": "ValueError", "error_message": "Test error", "context": "Test context", "traceback": "Traceback (most recent call last):\n  File \"/Users/kk/Code/whisperforge--prime/tests/test_basic_functionality.py\", line 32, in test_logging_functionality\n    raise ValueError(\"Test error\")\nValueError: Test error\n", "timestamp": "2025-06-11T19:23:22.945097"}
{"event": "error", "error_type": "ValueError", "error_message": "Test error for logging", "context": "Test error context", "traceback": "Traceback (most recent call last):\n  File \"/Users/kk/Code/whisperforge--prime/tests/test_basic_functionality.py\", line 167, in test_logging_error_handling\n    raise ValueError(\"Test error for logging\")\nValueError: Test error for logging\n", "timestamp": "2025-06-11T19:23:23.099713"}
{"event": "error", "error_type": "KeyError", "error_message": "'key_value'", "context": "Failed to load user preferences", "traceback": "Traceback (most recent call last):\n  File \"/Users/kk/Code/whisperforge--prime/core/auth_wrapper.py\", line 183, in _load_user_preferences\n    api_keys[item[\"key_name\"]] = item[\"key_value\"]\n                                 ~~~~^^^^^^^^^^^^^\nKeyError: 'key_value'\n", "timestamp": "2025-06-11T19:23:23.108696"}
{"event": "error", "error_type": "KeyError", "error_message": "'key_value'", "context": "Failed to load user preferences", "traceback": "Traceback (most recent call last):\n  File \"/Users/kk/Code/whisperforge--prime/core/auth_wrapper.py\", line 183, in _load_user_preferences\n    api_keys[item[\"key_name\"]] = item[\"key_value\"]\n                                 ~~~~^^^^^^^^^^^^^\nKeyError: 'key_value'\n", "timestamp": "2025-06-11T19:23:23.111381"}
{"step": "test_step", "status": "started", "timestamp": "2025-06-11T20:13:19.341635", "data": {}}
{"step": "test_step", "status": "completed", "timestamp": "2025-06-11T20:13:19.342631", "data": {}}
{"step": "test_step", "status": "failed", "timestamp": "2025-06-11T20:13:19.343386", "data": {"error": "Test error"}}
{"event": "file_upload", "filename": "test.wav", "size_mb": 1.5, "file_type": "audio/wav", "timestamp": "2025-06-11T20:13:19.344310"}
{"event": "error", "error_type": "ValueError", "error_message": "Test error", "context": "Test context", "traceback": "Traceback (most recent call last):\n  File \"/Users/kk/Code/whisperforge--prime/tests/test_basic_functionality.py\", line 32, in test_logging_functionality\n    raise ValueError(\"Test error\")\nValueError: Test error\n", "timestamp": "2025-06-11T20:13:19.347297"}
{"event": "error", "error_type": "ValueError", "error_message": "Test error for logging", "context": "Test error context", "traceback": "Traceback (most recent call last):\n  File \"/Users/kk/Code/whisperforge--prime/tests/test_basic_functionality.py\", line 167, in test_logging_error_handling\n    raise ValueError(\"Test error for logging\")\nValueError: Test error for logging\n", "timestamp": "2025-06-11T20:13:20.046303"}
{"event": "error", "error_type": "KeyError", "error_message": "'key_value'", "context": "Failed to load user preferences", "traceback": "Traceback (most recent call last):\n  File \"/Users/kk/Code/whisperforge--prime/core/auth_wrapper.py\", line 183, in _load_user_preferences\n    api_keys[item[\"key_name\"]] = item[\"key_value\"]\n                                 ~~~~^^^^^^^^^^^^^\nKeyError: 'key_value'\n", "timestamp": "2025-06-11T20:13:21.523872"}
{"event": "error", "error_type": "KeyError", "error_message": "'key_value'", "context": "Failed to load user preferences", "traceback": "Traceback (most recent call last):\n  File \"/Users/kk/Code/whisperforge--prime/core/auth_wrapper.py\", line 183, in _load_user_preferences\n    api_keys[item[\"key_name\"]] = item[\"key_value\"]\n                                 ~~~~^^^^^^^^^^^^^\nKeyError: 'key_value'\n", "timestamp": "2025-06-11T20:13:21.554791"}
{"step": "test_step", "status": "started", "timestamp": "2025-06-11T20:32:45.296843", "data": {}}
{"step": "test_step", "status": "completed", "timestamp": "2025-06-11T20:32:45.297138", "data": {}}
{"step": "test_step", "status": "failed", "timestamp": "2025-06-11T20:32:45.297241", "data": {"error": "Test error"}}
{"event": "file_upload", "filename": "test.wav", "size_mb": 1.5, "file_type": "audio/wav", "timestamp": "2025-06-11T20:32:45.297615"}
{"event": "error", "error_type": "ValueError", "error_message": "Test error", "context": "Test context", "traceback": "Traceback (most recent call last):\n  File \"/Users/kk/Code/whisperforge--prime/tests/test_basic_functionality.py\", line 32, in test_logging_functionality\n    raise ValueError(\"Test error\")\nValueError: Test error\n", "timestamp": "2025-06-11T20:32:45.298168"}
{"event": "error", "error_type": "ValueError", "error_message": "Test error for logging", "context": "Test error context", "traceback": "Traceback (most recent call last):\n  File \"/Users/kk/Code/whisperforge--prime/tests/test_basic_functionality.py\", line 167, in test_logging_error_handling\n    raise ValueError(\"Test error for logging\")\nValueError: Test error for logging\n", "timestamp": "2025-06-11T20:32:45.441270"}
{"event": "error", "error_type": "KeyError", "error_message": "'key_value'", "context": "Failed to load user preferences", "traceback": "Traceback (most recent call last):\n  File \"/Users/kk/Code/whisperforge--prime/core/auth_wrapper.py\", line 183, in _load_user_preferences\n    api_keys[item[\"key_name\"]] = item[\"key_value\"]\n                                 ~~~~^^^^^^^^^^^^^\nKeyError: 'key_value'\n", "timestamp": "2025-06-11T20:32:47.213480"}
{"event": "error", "error_type": "KeyError", "error_message": "'key_value'", "context": "Failed to load user preferences", "traceback": "Traceback (most recent call last):\n  File \"/Users/kk/Code/whisperforge--prime/core/auth_wrapper.py\", line 183, in _load_user_preferences\n    api_keys[item[\"key_name\"]] = item[\"key_value\"]\n                                 ~~~~^^^^^^^^^^^^^\nKeyError: 'key_value'\n", "timestamp": "2025-06-11T20:32:47.216417"}
{"step": "test_step", "status": "started", "timestamp": "2025-06-11T20:34:08.190003", "data": {}}
{"step": "test_step", "status": "completed", "timestamp": "2025-06-11T20:34:08.190185", "data": {}}
{"step": "test_step", "status": "failed", "timestamp": "2025-06-11T20:34:08.190472", "data": {"error": "Test error"}}
{"event": "file_upload", "filename": "test.wav", "size_mb": 1.5, "file_type": "audio/wav", "timestamp": "2025-06-11T20:34:08.190747"}
{"event": "error", "error_type": "ValueError", "error_message": "Test error", "context": "Test context", "traceback": "Traceback (most recent call last):\n  File \"/Users/kk/Code/whisperforge--prime/tests/test_basic_functionality.py\", line 32, in test_logging_functionality\n    raise ValueError(\"Test error\")\nValueError: Test error\n", "timestamp": "2025-06-11T20:34:08.191286"}
{"event": "error", "error_type": "ValueError", "error_message": "Test error for logging", "context": "Test error context", "traceback": "Traceback (most recent call last):\n  File \"/Users/kk/Code/whisperforge--prime/tests/test_basic_functionality.py\", line 167, in test_logging_error_handling\n    raise ValueError(\"Test error for logging\")\nValueError: Test error for logging\n", "timestamp": "2025-06-11T20:34:08.293011"}
{"event": "error", "error_type": "KeyError", "error_message": "'key_value'", "context": "Failed to load user preferences", "traceback": "Traceback (most recent call last):\n  File \"/Users/kk/Code/whisperforge--prime/core/auth_wrapper.py\", line 183, in _load_user_preferences\n    api_keys[item[\"key_name\"]] = item[\"key_value\"]\n                                 ~~~~^^^^^^^^^^^^^\nKeyError: 'key_value'\n", "timestamp": "2025-06-11T20:34:09.880845"}
{"event": "error", "error_type": "KeyError", "error_message": "'key_value'", "context": "Failed to load user preferences", "traceback": "Traceback (most recent call last):\n  File \"/Users/kk/Code/whisperforge--prime/core/auth_wrapper.py\", line 183, in _load_user_preferences\n    api_keys[item[\"key_name\"]] = item[\"key_value\"]\n                                 ~~~~^^^^^^^^^^^^^\nKeyError: 'key_value'\n", "timestamp": "2025-06-11T20:34:09.884245"}
{"event": "error", "error_type": "ValueError", "error_message": "SUPABASE_URL and SUPABASE_ANON_KEY must be set in environment variables", "context": "Failed to initialize Supabase", "traceback": "Traceback (most recent call last):\n  File \"/Users/kk/Code/whisperforge--prime/core/auth_wrapper.py\", line 30, in _init_supabase\n    self.supabase_client = get_supabase_client()\n                           ~~~~~~~~~~~~~~~~~~~^^\n  File \"/Users/kk/Code/whisperforge--prime/core/supabase_integration.py\", line 397, in get_supabase_client\n    _supabase_client = SupabaseClient()\n  File \"/Users/kk/Code/whisperforge--prime/core/supabase_integration.py\", line 36, in __init__\n    raise ValueError(\"SUPABASE_URL and SUPABASE_ANON_KEY must be set in environment variables\")\nValueError: SUPABASE_URL and SUPABASE_ANON_KEY must be set in environment variables\n", "timestamp": "2025-06-11T23:48:52.099846"}
